<?xml version="1.0"?>
<robot name="spider">

  <!-- Spider body (cylinder) -->
  <link name="body">
    <inertial>
      <mass value="1.0"/>
      <origin xyz="0 0 0" rpy="0 0 0"/>
      <inertia ixx="0.00542" iyy="0.00542" izz="0.01" ixy="0.0" ixz="0.0" iyz="0.0"/>
    </inertial>
    <visual>
      <origin xyz="0 0 0" rpy="0 0 0"/>
      <geometry>
        <cylinder radius="0.1" length="0.05"/>
      </geometry>
      <material name="grey">
        <color rgba="0.5 0.5 0.5 1.0"/>
      </material>
    </visual>
    <collision>
      <origin xyz="0 0 0" rpy="0 0 0"/>
      <geometry>
        <cylinder radius="0.1" length="0.05"/>
      </geometry>
    </collision>
  </link>

  <!-- Define 3 legs spaced at 120 degrees -->

  <!-- Leg 1 -->
  <link name="thigh_leg1">
    <inertial>
      <mass value="0.5"/>
      <origin xyz="0.1 0 0" rpy="0 0 0"/>
      <inertia ixx="0.00042" iyy="0.00167" izz="0.00167" ixy="0.0" ixz="0.0" iyz="0.0"/>
    </inertial>
    <visual>
      <origin xyz="0.1 0 0" rpy="0 0 0"/>
      <geometry>
        <box size="0.2 0.05 0.05"/>
      </geometry>
      <material name="red">
        <color rgba="1 0 0 1"/>
      </material>
    </visual>
    <collision>
      <origin xyz="0.1 0 0" rpy="0 0 0"/>
      <geometry>
        <box size="0.2 0.05 0.05"/>
      </geometry>
    </collision>
  </link>

  <link name="shin_leg1">
    <inertial>
      <mass value="0.3"/>
      <origin xyz="0.1 0 0" rpy="0 0 0"/>
      <inertia ixx="0.00025" iyy="0.001" izz="0.001" ixy="0.0" ixz="0.0" iyz="0.0"/>
    </inertial>
    <visual>
      <origin xyz="0.1 0 0" rpy="0 0 0"/>
      <geometry>
        <box size="0.2 0.05 0.05"/>
      </geometry>
      <material name="blue">
        <color rgba="0 0 1 1"/>
      </material>
    </visual>
    <collision>
      <origin xyz="0.1 0 0" rpy="0 0 0"/>
      <geometry>
        <box size="0.2 0.05 0.05"/>
      </geometry>
    </collision>
  </link>

  <!-- Hip joint connecting body to thigh of leg 1 at 0 degrees -->
  <joint name="hip_joint_leg1" type="revolute">
    <origin xyz="0.1 0 0" rpy="0 1.5708 0"/>
    <parent link="body"/>
    <child link="thigh_leg1"/>
    <axis xyz="0 1 0"/>
    <limit lower="-1.57" upper="1.57" effort="1.0" velocity="1.0"/>
  </joint>

  <!-- Knee joint connecting thigh to shin of leg 1 -->
  <joint name="knee_joint_leg1" type="revolute">
    <origin xyz="0.2 0 0" rpy="0 0 0"/>
    <parent link="thigh_leg1"/>
    <child link="shin_leg1"/>
    <axis xyz="0 1 0"/>
    <limit lower="-1.57" upper="1.57" effort="1.0" velocity="1.0"/>
  </joint>

  <!-- Actuator for hip joint of leg 1 -->
  <transmission name="hip_trans_leg1" type="SimpleTransmission">
    <type>transmission_interface/SimpleTransmission</type>
    <actuator name="hip_motor_leg1">
      <mechanicalReduction>1</mechanicalReduction>
    </actuator>
    <joint name="hip_joint_leg1">
      <hardwareInterface>hardware_interface/PositionJointInterface</hardwareInterface>
    </joint>
  </transmission>

  <!-- Actuator for knee joint of leg 1 -->
  <transmission name="knee_trans_leg1" type="SimpleTransmission">
    <type>transmission_interface/SimpleTransmission</type>
    <actuator name="knee_motor_leg1">
      <mechanicalReduction>1</mechanicalReduction>
    </actuator>
    <joint name="knee_joint_leg1">
      <hardwareInterface>hardware_interface/PositionJointInterface</hardwareInterface>
    </joint>
  </transmission>

  <!-- Leg 2 -->
  <link name="thigh_leg2">
    <inertial>
      <mass value="0.5"/>
      <origin xyz="0.1 0 0" rpy="0 0 0"/>
      <inertia ixx="0.00042" iyy="0.00167" izz="0.00167" ixy="0.0" ixz="0.0" iyz="0.0"/>
    </inertial>
    <visual>
      <origin xyz="0.1 0 0" rpy="0 0 0"/>
      <geometry>
        <box size="0.2 0.05 0.05"/>
      </geometry>
      <material name="red"/>
    </visual>
    <collision>
      <origin xyz="0.1 0 0" rpy="0 0 0"/>
      <geometry>
        <box size="0.2 0.05 0.05"/>
      </geometry>
    </collision>
  </link>

  <link name="shin_leg2">
    <inertial>
      <mass value="0.3"/>
      <origin xyz="0.1 0 0" rpy="0 0 0"/>
      <inertia ixx="0.00025" iyy="0.001" izz="0.001" ixy="0.0" ixz="0.0" iyz="0.0"/>
    </inertial>
    <visual>
      <origin xyz="0.1 0 0" rpy="0 0 0"/>
      <geometry>
        <box size="0.2 0.05 0.05"/>
      </geometry>
      <material name="blue"/>
    </visual>
    <collision>
      <origin xyz="0.1 0 0" rpy="0 0 0"/>
      <geometry>
        <box size="0.2 0.05 0.05"/>
      </geometry>
    </collision>
  </link>

  <!-- Hip joint connecting body to thigh of leg 2 at 120 degrees -->
  <joint name="hip_joint_leg2" type="revolute">
    <origin xyz="-0.05 0.0866 0" rpy="0 1.5708 2.0944"/> <!-- 120 degrees in radians -->
    <parent link="body"/>
    <child link="thigh_leg2"/>
    <axis xyz="0 1 0"/>
    <limit lower="-1.57" upper="1.57" effort="1.0" velocity="1.0"/>
  </joint>

  <!-- Knee joint connecting thigh to shin of leg 2 -->
  <joint name="knee_joint_leg2" type="revolute">
    <origin xyz="0.2 0 0" rpy="0 0 0"/>
    <parent link="thigh_leg2"/>
    <child link="shin_leg2"/>
    <axis xyz="0 1 0"/>
    <limit lower="-1.57" upper="1.57" effort="1.0" velocity="1.0"/>
  </joint>

  <!-- Actuator for hip joint of leg 2 -->
  <transmission name="hip_trans_leg2" type="SimpleTransmission">
    <type>transmission_interface/SimpleTransmission</type>
    <actuator name="hip_motor_leg2">
      <mechanicalReduction>1</mechanicalReduction>
    </actuator>
    <joint name="hip_joint_leg2">
      <hardwareInterface>hardware_interface/PositionJointInterface</hardwareInterface>
    </joint>
  </transmission>

  <!-- Actuator for knee joint of leg 2 -->
  <transmission name="knee_trans_leg2" type="SimpleTransmission">
    <type>transmission_interface/SimpleTransmission</type>
    <actuator name="knee_motor_leg2">
      <mechanicalReduction>1</mechanicalReduction>
    </actuator>
    <joint name="knee_joint_leg2">
      <hardwareInterface>hardware_interface/PositionJointInterface</hardwareInterface>
    </joint>
  </transmission>

  <!-- Leg 3 -->
  <link name="thigh_leg3">
    <inertial>
      <mass value="0.5"/>
      <origin xyz="0.1 0 0" rpy="0 0 0"/>
      <inertia ixx="0.00042" iyy="0.00167" izz="0.00167" ixy="0.0" ixz="0.0" iyz="0.0"/>
    </inertial>
    <visual>
      <origin xyz="0.1 0 0" rpy="0 0 0"/>
      <geometry>
        <box size="0.2 0.05 0.05"/>
      </geometry>
      <material name="red"/>
    </visual>
    <collision>
      <origin xyz="0.1 0 0" rpy="0 0 0"/>
      <geometry>
        <box size="0.2 0.05 0.05"/>
      </geometry>
    </collision>
  </link>

  <link name="shin_leg3">
    <inertial>
      <mass value="0.3"/>
      <origin xyz="0.1 0 0" rpy="0 0 0"/>
      <inertia ixx="0.00025" iyy="0.001" izz="0.001" ixy="0.0" ixz="0.0" iyz="0.0"/>
    </inertial>
    <visual>
      <origin xyz="0.1 0 0" rpy="0 0 0"/>
      <geometry>
        <box size="0.2 0.05 0.05"/>
      </geometry>
      <material name="blue"/>
    </visual>
    <collision>
      <origin xyz="0.1 0 0" rpy="0 0 0"/>
      <geometry>
        <box size="0.2 0.05 0.05"/>
      </geometry>
    </collision>
  </link>

  <!-- Hip joint connecting body to thigh of leg 3 at 240 degrees -->
  <joint name="hip_joint_leg3" type="revolute">
    <origin xyz="-0.05 -0.0866 0" rpy="0 1.5708 4.18879"/> <!-- 240 degrees in radians -->
    <parent link="body"/>
    <child link="thigh_leg3"/>
    <axis xyz="0 1 0"/>
    <limit lower="-1.57" upper="1.57" effort="1.0" velocity="1.0"/>
  </joint>

  <!-- Knee joint connecting thigh to shin of leg 3 -->
  <joint name="knee_joint_leg3" type="revolute">
    <origin xyz="0.2 0 0" rpy="0 0 0"/>
    <parent link="thigh_leg3"/>
    <child link="shin_leg3"/>
    <axis xyz="0 1 0"/>
    <limit lower="-1.57" upper="1.57" effort="1.0" velocity="1.0"/>
  </joint>

  <!-- Actuator for hip joint of leg 3 -->
  <transmission name="hip_trans_leg3" type="SimpleTransmission">
    <type>transmission_interface/SimpleTransmission</type>
    <actuator name="hip_motor_leg3">
      <mechanicalReduction>1</mechanicalReduction>
    </actuator>
    <joint name="hip_joint_leg3">
      <hardwareInterface>hardware_interface/PositionJointInterface</hardwareInterface>
    </joint>
  </transmission>

  <!-- Actuator for knee joint of leg 3 -->
  <transmission name="knee_trans_leg3" type="SimpleTransmission">
    <type>transmission_interface/SimpleTransmission</type>
    <actuator name="knee_motor_leg3">
      <mechanicalReduction>1</mechanicalReduction>
    </actuator>
    <joint name="knee_joint_leg3">
      <hardwareInterface>hardware_interface/PositionJointInterface</hardwareInterface>
    </joint>
  </transmission>

</robot>